Workbook

Sheet Anexo A
E2: DIRECCIÓN GENERAL DE IMPUESTOS INTERNOS
E3: DECLARACIÓN JURADA Y/O PAGO DEL IMPUESTO SOBRE LAS TRANSFERENCIAS DE BIENES INDUSTRIALIZADOS Y SERVICIOS (ITBIS)
B5: I. | C5: DATOS GENERALES | Z5: =+IF(#REF!="",1,2) -> #REF!
C6: RNC/CÉDULA | I6: RAZÓN SOCIAL/NOMBRE | Q6: NOMBRE COMERCIAL
D9: CORREO ELECTRÓNICO | M9: TELÉFONO | Q9: PERÍODO (MES/AÑO) | T9: FECHA LÍMITE DE PAGO | W9: TIPO DE DECLARACIÓN
B14: II. | C14: OPERACIONES REPORTADAS EN EL 607, LIBRO DE VENTAS Y FACTURA ELECTRONICA (E-NCF) POR TIPO DE NCF | T14: CANTIDAD | W14: MONTO
B15: 1 | C15: COMPROBANTES VÁLIDO PARA CRÉDITO FISCAL (01 y 31) | V15: +
B16: =+B15+1 -> 2 | C16: COMPROBANTES CONSUMO (02 y 32) | V16: +
B17: =+B16+1 -> 3 | C17: COMPROBANTES NOTA DE DÉBITO (03 y 33) | V17: +
B18: =+B17+1 -> 4 | C18: COMPROBANTES NOTA DE CRÉDITO (04 y 34) | V18: -
B19: =+B18+1 -> 5 | C19: COMPROBANTES REGISTRO ÚNICO DE INGRESOS (12) | V19: +
B20: =+B19+1 -> 6 | C20: COMPROBANTES REGISTRO REGIMENES ESPECIALES (14 y 44) | V20: +
B21: =+B20+1 -> 7 | C21: COMPROBANTES GUBERNAMENTALES (15 y 45) | V21: +
B22: =+B21+1 -> 8 | C22: COMPROBANTES PARA EXPORTACIONES (16 y 46) | V22: +
B23: =+B22+1 -> 9 | C23: OTRAS OPERACIONES (POSITIVAS) | V23: +
B24: =+B23+1 -> 10 | C24: OTRAS OPERACIONES (NEGATIVAS) | V24: -
B25: =+B24+1 -> 11 | C25: TOTAL OPERACIONES (Sumar casillas 1+2+3-4+5+6+7+8+9-10) | V25: = | W25: =W15+W16+W17+W19+W20+W21+W22+W23-W18-W24 -> 0
B27: III. | C27: OPERACIONES REPORTADAS EN EL 607/LIBRO DE VENTAS Y FACTURA ELECTRONICA (E-NCF) POR TIPO DE VENTA (MONTO TOTAL INCLUYENDO IMPUESTOS) | W27: MONTO BRUTO
B28: =+B25+1 -> 12 | C28: EFECTIVO | V28: +
B29: =+B28+1 -> 13 | C29: CHEQUE / TRANSFERENCIA | V29: +
B30: =+B29+1 -> 14 | C30: TARJETA DÉBITO / CRÉDITO | V30: +
B31: =+B30+1 -> 15 | C31: A CRÉDITO | V31: +
B32: =+B31+1 -> 16 | C32: BONOS O CERTIFICADO DE REGALO | V32: +
B33: =+B32+1 -> 17 | C33: PERMUTAS | V33: +
B34: =+B33+1 -> 18 | C34: OTRAS FORMAS DE VENTA | V34: +
B35: =+B34+1 -> 19 | C35: TOTAL OPERACIONES POR TIPO DE VENTA (Sumar casillas 12+13+14+15+16+17+18) | V35: = | W35: =ABS(SUM(W28:X34)) -> 0
B37: IV. | C37: OPERACIONES REPORTADAS EN EL 607/LIBRO DE VENTAS Y FACTURA ELECTRONICA (E-NCF) POR TIPO DE INGRESO | W37: MONTO
B38: =+B35+1 -> 20 | C38: INGRESOS POR OPERACIONES (NO FINANCIEROS) | V38: +
B39: =+B38+1 -> 21 | C39: INGRESOS FINANCIEROS | V39: +
B40: =+B39+1 -> 22 | C40: INGRESOS EXTRAORDINARIOS | V40: +
B41: =+B40+1 -> 23 | C41: INGRESOS POR ARRENDAMIENTOS | V41: +
B42: =+B41+1 -> 24 | C42: INGRESOS POR VENTAS DE ACTIVOS DEPRECIABLES | V42: +
B43: =+B42+1 -> 25 | C43: OTROS INGRESOS | V43: +
B44: =+B43+1 -> 26 | C44: TOTAL POR TIPO DE INGRESO (Sumar casillas 20+21+22+23+24+25) | V44: = | W44: =ABS(SUM(W38:X43)) -> 0
B46: V. | C46: PAGOS COMPUTABLES POR RETENCIONES/PERCEPCIÓN | W46: MONTO
B47: =B44+1 -> 27 | C47: PAGOS COMPUTABLES POR RETENCIONES (Norma No. 08-04) | V47: +
B48: =+B47+1 -> 28 | C48: PAGOS COMPUTABLES POR VENTAS DE PASAJES DE TRANSPORTE AÉREO (Norma No. 02-05) (BSP-IATA) | V48: +
B49: =+B48+1 -> 29 | C49: PAGOS COMPUTABLES POR OTRAS RETENCIONES (Norma No. 02-05) | V49: +
B50: =+B49+1 -> 30 | C50: PAGOS COMPUTABLES POR VENTAS DE PAQUETES DE ALOJAMIENTO Y OCUPACIÓN | V50: +
B51: =+B50+1 -> 31 | C51: CRÉDITO POR RETENCIÓN REALIZADA POR ENTIDADES DEL ESTADO | V51: +
...

Sheet IT-1
E2: DIRECCIÓN GENERAL DE IMPUESTOS INTERNOS
E3: DECLARACIÓN JURADA Y/O PAGO DEL IMPUESTO SOBRE LAS TRANSFERENCIAS DE BIENES INDUSTRIALIZADOS Y SERVICIOS (ITBIS)
B5: I. | C5: DATOS GENERALES | Z5: =IF(V14=0,1,2) -> 1
C6: RNC/CÉDULA | I6: RAZÓN SOCIAL/NOMBRE | P6: NOMBRE COMERCIAL
D9: CORREO ELECTRÓNICO | M9: TELÉFONO | P9: PERÍODO (MES/AÑO) | S9: FECHA LÍMITE DE PAGO | V9: TIPO DE DECLARACIÓN
B13: II. | C13: INGRESOS POR OPERACIONES | V13: MONTO
B14: 1 | C14: TOTAL DE OPERACIONES DEL PERIODO (Proviene de la casilla 11 del Anexo A) | U14: + | V14: ='Anexo A'!W25 -> 0
B15: II.A | C15: NO GRAVADAS
B16: =+B14+1 -> 2 | C16: INGRESOS POR EXPORTACIONES DE BIENES SEGÚN Art. 342 CT | U16: +
B17: =+B16+1 -> 3 | C17: INGRESOS POR EXPORTACIONES DE SERVICIOS SEGÚN Art. 344 CT y Art. 14 Literal j), Reglamento 293-11 | U17: +
B18: =+B17+1 -> 4 | C18: INGRESOS POR VENTAS LOCALES DE BIENES O SERVICIOS EXENTOS Art. 343 y Art. 344 CT | U18: +
B19: =+B18+1 -> 5 | C19: INGRESOS POR VENTAS DE BIENES O SERVICIOS EXENTOS POR DESTINO | U19: +
B20: =+B19+1 -> 6 | C20: NO SUJETAS A ITBIS POR SERVICIOS DE CONSTRUCCIÓN (Proviene de la casilla 38 del Anexo A) | U20: + | V20: ='Anexo A'!W60 -> 0
B21: =+B20+1 -> 7 | C21: NO SUJETAS A ITBIS POR COMISIONES (Proviene de la casilla 42 del Anexo A) | U21: + | V21: ='Anexo A'!W66 -> 0
B22: =+B21+1 -> 8 | C22: INGRESOS POR VENTAS LOCALES DE BIENES EXENTOS SEGÚN Párrafos III y IV, Art. 343 CT | U22: +
B23: =+B22+1 -> 9 | C23: TOTAL INGRESOS POR OPERACIONES NO GRAVADAS (Sumar casillas 2+3+4+5+6+7+8) | U23: = | V23: =ABS(+V16+V17+V18+V19+V20+V21+V22) -> 0
B24: II.B | C24: GRAVADAS
B25: =+B23+1 -> 10 | C25: TOTAL INGRESOS POR OPERACIONES GRAVADAS (Restar casillas 1-9) | U25: = | V25: =ABS(IF((V14-V23)>0,ABS((V14-V23)),0)) -> 0
B26: =+B25+1 -> 11 | C26: OPERACIONES GRAVADAS AL 18% | U26: =
B27: =+B26+1 -> 12 | C27: OPERACIONES GRAVADAS AL 16% | U27: =
B28: =+B27+1 -> 13 | C28: OPERACIONES GRAVADAS AL 9% (Ley No. 690-16) | U28: =
B29: =+B28+1 -> 14 | C29: OPERACIONES GRAVADAS AL 8% (Ley No. 690-16) | U29: =
B30: =+B29+1 -> 15 | C30: OPERACIONES GRAVADAS POR VENTAS DE ACTIVOS DEPRECIABLES (Categoría 2 y 3) | U30: =
B31: =IF((V26+V27+V28+V29+V30)<>V25,"La sumatoria de las casillas 11+12+13+14+15 debe ser igual al valor de la casilla 10.","")
B32: III. | C32: LIQUIDACIÓN | V32: MONTO
B33: =B30+1 -> 16 | C33: ITBIS COBRADO (18% de la casilla 11) | U33: + | V33: =ABS(+V26*18%) -> 0
B34: =+B33+1 -> 17 | C34: ITBIS COBRADO (16% de la casilla 12) | U34: + | V34: =ABS(+V27*16%) -> 0
B35: =+B34+1 -> 18 | C35: ITBIS COBRADO (9% de la casilla 13) (Ley No. 690-16) | U35: + | V35: =ABS(V28*9%) -> 0
B36: =+B35+1 -> 19 | C36: ITBIS COBRADO (8% de la casilla 14) (Ley No. 690-16) | U36: + | V36: =ABS(V29*8%) -> 0
B37: =+B36+1 -> 20 | C37: ITBIS COBRADO POR VENTAS DE ACTIVOS DEPRECIABLES (Categoría 2 y 3) (18% de la casilla 15) | U37: + | V37: =ABS(+V30*18%) -> 0
B38: =+B37+1 -> 21 | C38: TOTAL ITBIS COBRADO (Sumar casillas 16+17+18+19+20) | U38: = | V38: =ABS(V33+V34+V35+V36+V37) -> 0
B39: =+B38+1 -> 22 | C39: ITBIS PAGADO EN COMPRAS LOCALES (Proviene de la casilla 56 del Anexo A) | U39: + | V39: =+'Anexo A'!O87 -> 0
B40: =+B39+1 -> 23 | C40: ITBIS PAGADO POR SERVICIOS DEDUCIBLES (Proviene de la casilla 56 del Anexo A) | U40: + | V40: =+'Anexo A'!P87 -> 0
B41: =+B40+1 -> 24 | C41: ITBIS PAGADO EN IMPORTACIONES (Proviene de la casilla 56 del Anexo A) | U41: + | V41: =+'Anexo A'!T87 -> 0
B42: =+B41+1 -> 25 | C42: TOTAL ITBIS DEDUCIBLE (Sumar casillas 22+23+24) | U42: = | V42: =ABS(V39+V40+V41) -> 0
B43: =+B42+1 -> 26 | C43: IMPUESTO A PAGAR (Si el valor de las casillas 21-25 es Positivo) | U43: = | V43: =ABS(IF((V38-V42)>0,((V38-V42)),0)) -> 0
B44: =+B43+1 -> 27 | C44: SALDO A FAVOR (Si el valor de las casillas 21-25 es Negativo) | U44: = | V44: =ABS(IF((V38-V42)<0,(V38-V42),0)) -> 0
B45: =+B44+1 -> 28 | C45: SALDOS COMPENSABLES AUTORIZADOS (Otros Impuestos) Y/O REEMBOLSOS | U45: ±
B46: =+B45+1 -> 29 | C46: SALDO A FAVOR ANTERIOR | U46: -
B47: =+B46+1 -> 30 | C47: TOTAL PAGOS COMPUTABLES POR RETENCIONES (Proviene de la casilla 33 del Anexo A) | U47: - | V47: ='Anexo A'!W53 -> 0
...
